Workbook

Sheet hi!
A1: The Viscose Benches
A3: Welcome to the Viscose Benches! Here are some things you should know:
B4: • To use this sheet: in the top left, click File → Make a Copy.
B6: • I picked out scenarios that I personally found the most helpful for ingame translation and technique improvement. While they are in benchmark form, this is more of a practice playlist disguised as a benchmark. That's why there are such a large number of scenarios and why some categories are underrepresented.
B8: • One of the issues I tried to address with these benches is how going between Intermediate and Advanced can feel like a huge jump. To fix this, I have added additional ranks in each difficulty, and left some overlap between them with the intent that people play two sets of benchmarks simultaneously to vary their focus. I'd recommend beginner players try intermediate if they can comfortable get mammoth scores, and players on the intermediate benchmarks try advanced once they are around lavender/indigo.
B10: • In order to get a rank, you need to get at least one score in each subcategory. It's hard and it takes forever to get a rank, but I want to push people to be well rounded.
B12: • The number next to each scenario is your accumulated threads. The closer you are to the top score requirement on a given scenario, the more threads you receive. This gives you a look at the overall strength of your scoresheet, but doesn't actually affect your rank. Your total threads is summed at the top.
B14: • Currently, the score targets are prospective. On each difficulty, we have a link in the top right to a feedback form. Please send your sheets and opinions so we can balance these targets!
B16: • For categories like Arm, Wrist, and Fingertips, these scenarios are categorized by what muscle group I think they stress the most. These classifications can break at certain sensitivities, but I found these scenarios to target those particular muscle groups very effectively in practice. Scores slower than 50cm on fingertip scenarios are invalid, and 103hfov is the minimum for all scenarios.
B18: • If you click any scenario name, I have left a comment that tells you how to get the most out of each scenario and what to focus on while you practice. (WIP)
B19: • The difficulty of each tab of benchmarks refers to the relative difficulty of the scenarios in them, not the skill of the players who should be playing them. Medium difficulty scenarios feature ranks stretching well into what would be exclusive to the advanced benchmarks on voltaic
B20: • This sheet is a joint project between myself and pinguefy! Feel free to @ pingu in the Raw Input discord if you run into any issues or want to provide suggestions.
A21: My links: | F21: pingu's links:
A22: YouTube | F22: YouTube
A23: 2nd Channel | F23: 2nd Channel
A24: Twitter | F24: Twitter
A25: Twitch | F25: Raw Input Discord
A26: Patreon | F26: @jvniper on Discord
A27: My Discord | F27: Raw Input Podcast (aim podcast with us two + MissColourz)

Sheet Easier Scenarios
A1: Viscose Easier Scenarios | E1: =brank!A1 -> Unranked | H1: ="Playlist Code: " -> Playlist Code: | J1: KovaaKsGearingMehLowground
C2: Scenario | D2: =round((sum(brank!D2:brank!D37)*100),0) -> 0 | E2: =" High Score" -> High Score | G2: Progress | H2: Lemming | I2: Hare | J2: Ermine | K2: Penguin | L2: Fox | M2: Mammoth | N2: Orca | O2: Seal
A3: Control Tracking | B3: Arm | C3: =IFERROR(__xludf.DUMMYFUNCTION("importrange(""https://docs.google.com/spreadsheets/d/1k3XRRwn-mAbvb3rXIODFPrsnkgSEfh0xg1EWJICcSPo/edit?usp=sharing"",""Beginner!C3:C38"")"),"WhisphereRawControl Larger + Slowed") -> WhisphereRawControl Larger + Slowed | D3: =round(brank!$D2*100,0)&"%" -> 0% | G3: =IFERROR(__xludf.DUMMYFUNCTION("sparkline( F3 - choose(match(F3, {0, H3:O3}), 0, H3, I3, J3, K3, L3, M3, N3, O3), { ""charttype"", ""bar""; ""max"", choose(match(F3, {0, H3:O3}), H3, I3-H3, J3-I3, K3-J3, L3-K3, M3-L3, N3-M3, O3-N3, 0); ""nan"", ""ignore""; ""color1"""&", iferror(choose(match(F3, {0, H3:O3}), ""#C5C3F2"", ""#B2CBEA"", ""#BAF6FC"", ""#6B94DF"", ""#5558AA"", ""#6e3f98"", ""#C080E4"", ""#F5BDE8"", ""#F5BDE8"" )) } )"),"") | H3: =IFERROR(__xludf.DUMMYFUNCTION("importrange(""https://docs.google.com/spreadsheets/d/1k3XRRwn-mAbvb3rXIODFPrsnkgSEfh0xg1EWJICcSPo/edit?gid=0#gid=0"",""Beginner!D3:K38"")"),5500.0) -> 5500 | I3: =IFERROR(__xludf.DUMMYFUNCTION("""COMPUTED_VALUE"""),6700.0) -> 6700 | J3: =IFERROR(__xludf.DUMMYFUNCTION("""COMPUTED_VALUE"""),7800.0) -> 7800 | K3: =IFERROR(__xludf.DUMMYFUNCTION("""COMPUTED_VALUE"""),8700.0) -> 8700 | L3: =IFERROR(__xludf.DUMMYFUNCTION("""COMPUTED_VALUE"""),9600.0) -> 9600 | M3: =IFERROR(__xludf.DUMMYFUNCTION("""COMPUTED_VALUE"""),10500.0) -> 10500 | N3: =IFERROR(__xludf.DUMMYFUNCTION("""COMPUTED_VALUE"""),11400.0) -> 11400 | O3: =IFERROR(__xludf.DUMMYFUNCTION("""COMPUTED_VALUE"""),12500.0) -> 12500
C4: =IFERROR(__xludf.DUMMYFUNCTION("""COMPUTED_VALUE"""),"Whisphere 80%") -> Whisphere 80% | D4: =round(brank!$D3*100,0)&"%" -> 0% | G4: =IFERROR(__xludf.DUMMYFUNCTION("sparkline( F4 - choose(match(F4, {0, H4:O4}), 0, H4, I4, J4, K4, L4, M4, N4, O4), { ""charttype"", ""bar""; ""max"", choose(match(F4, {0, H4:O4}), H4, I4-H4, J4-I4, K4-J4, L4-K4, M4-L4, N4-M4, O4-N4, 0); ""nan"", ""ignore""; ""color1"""&", iferror(choose(match(F4, {0, H4:O4}), ""#C5C3F2"", ""#B2CBEA"", ""#BAF6FC"", ""#6B94DF"", ""#5558AA"", ""#6e3f98"", ""#C080E4"", ""#F5BDE8"", ""#F5BDE8"" )) } )"),"") | H4: =IFERROR(__xludf.DUMMYFUNCTION("""COMPUTED_VALUE"""),6300.0) -> 6300 | I4: =IFERROR(__xludf.DUMMYFUNCTION("""COMPUTED_VALUE"""),7700.0) -> 7700 | J4: =IFERROR(__xludf.DUMMYFUNCTION("""COMPUTED_VALUE"""),9000.0) -> 9000 | K4: =IFERROR(__xludf.DUMMYFUNCTION("""COMPUTED_VALUE"""),10000.0) -> 10000 | L4: =IFERROR(__xludf.DUMMYFUNCTION("""COMPUTED_VALUE"""),11000.0) -> 11000 | M4: =IFERROR(__xludf.DUMMYFUNCTION("""COMPUTED_VALUE"""),12000.0) -> 12000 | N4: =IFERROR(__xludf.DUMMYFUNCTION("""COMPUTED_VALUE"""),13000.0) -> 13000 | O4: =IFERROR(__xludf.DUMMYFUNCTION("""COMPUTED_VALUE"""),14500.0) -> 14500
C5: =IFERROR(__xludf.DUMMYFUNCTION("""COMPUTED_VALUE"""),"Smoothbot Invincible Goated 75%") -> Smoothbot Invincible Goated 75% | D5: =round(brank!$D4*100,0)&"%" -> 0% | G5: =IFERROR(__xludf.DUMMYFUNCTION("sparkline( F5 - choose(match(F5, {0, H5:O5}), 0, H5, I5, J5, K5, L5, M5, N5, O5), { ""charttype"", ""bar""; ""max"", choose(match(F5, {0, H5:O5}), H5, I5-H5, J5-I5, K5-J5, L5-K5, M5-L5, N5-M5, O5-N5, 0); ""nan"", ""ignore""; ""color1"""&", iferror(choose(match(F5, {0, H5:O5}), ""#C5C3F2"", ""#B2CBEA"", ""#BAF6FC"", ""#6B94DF"", ""#5558AA"", ""#6e3f98"", ""#C080E4"", ""#F5BDE8"", ""#F5BDE8"" )) } )"),"") | H5: =IFERROR(__xludf.DUMMYFUNCTION("""COMPUTED_VALUE"""),1800.0) -> 1800 | I5: =IFERROR(__xludf.DUMMYFUNCTION("""COMPUTED_VALUE"""),2250.0) -> 2250 | J5: =IFERROR(__xludf.DUMMYFUNCTION("""COMPUTED_VALUE"""),2650.0) -> 2650 | K5: =IFERROR(__xludf.DUMMYFUNCTION("""COMPUTED_VALUE"""),2900.0) -> 2900 | L5: =IFERROR(__xludf.DUMMYFUNCTION("""COMPUTED_VALUE"""),3150.0) -> 3150 | M5: =IFERROR(__xludf.DUMMYFUNCTION("""COMPUTED_VALUE"""),3400.0) -> 3400 | N5: =IFERROR(__xludf.DUMMYFUNCTION("""COMPUTED_VALUE"""),3650.0) -> 3650 | O5: =IFERROR(__xludf.DUMMYFUNCTION("""COMPUTED_VALUE"""),4000.0) -> 4000
B6: Wrist | C6: =IFERROR(__xludf.DUMMYFUNCTION("""COMPUTED_VALUE"""),"Leaptrack Goated 60% Larger") -> Leaptrack Goated 60% Larger | D6: =round(brank!$D5*100,0)&"%" -> 0% | G6: =IFERROR(__xludf.DUMMYFUNCTION("sparkline( F6 - choose(match(F6, {0, H6:O6}), 0, H6, I6, J6, K6, L6, M6, N6, O6), { ""charttype"", ""bar""; ""max"", choose(match(F6, {0, H6:O6}), H6, I6-H6, J6-I6, K6-J6, L6-K6, M6-L6, N6-M6, O6-N6, 0); ""nan"", ""ignore""; ""color1"""&", iferror(choose(match(F6, {0, H6:O6}), ""#C5C3F2"", ""#B2CBEA"", ""#BAF6FC"", ""#6B94DF"", ""#5558AA"", ""#6e3f98"", ""#C080E4"", ""#F5BDE8"", ""#F5BDE8"" )) } )"),"") | H6: =IFERROR(__xludf.DUMMYFUNCTION("""COMPUTED_VALUE"""),850.0) -> 850 | I6: =IFERROR(__xludf.DUMMYFUNCTION("""COMPUTED_VALUE"""),1200.0) -> 1200 | J6: =IFERROR(__xludf.DUMMYFUNCTION("""COMPUTED_VALUE"""),1500.0) -> 1500 | K6: =IFERROR(__xludf.DUMMYFUNCTION("""COMPUTED_VALUE"""),1700.0) -> 1700 | L6: =IFERROR(__xludf.DUMMYFUNCTION("""COMPUTED_VALUE"""),1900.0) -> 1900 | M6: =IFERROR(__xludf.DUMMYFUNCTION("""COMPUTED_VALUE"""),2100.0) -> 2100 | N6: =IFERROR(__xludf.DUMMYFUNCTION("""COMPUTED_VALUE"""),2250.0) -> 2250 | O6: =IFERROR(__xludf.DUMMYFUNCTION("""COMPUTED_VALUE"""),2450.0) -> 2450
C7: =IFERROR(__xludf.DUMMYFUNCTION("""COMPUTED_VALUE"""),"Controlsphere rAim Easy 90%") -> Controlsphere rAim Easy 90% | D7: =round(brank!$D6*100,0)&"%" -> 0% | G7: =IFERROR(__xludf.DUMMYFUNCTION("sparkline( F7 - choose(match(F7, {0, H7:O7}), 0, H7, I7, J7, K7, L7, M7, N7, O7), { ""charttype"", ""bar""; ""max"", choose(match(F7, {0, H7:O7}), H7, I7-H7, J7-I7, K7-J7, L7-K7, M7-L7, N7-M7, O7-N7, 0); ""nan"", ""ignore""; ""color1"""&", iferror(choose(match(F7, {0, H7:O7}), ""#C5C3F2"", ""#B2CBEA"", ""#BAF6FC"", ""#6B94DF"", ""#5558AA"", ""#6e3f98"", ""#C080E4"", ""#F5BDE8"", ""#F5BDE8"" )) } )"),"") | H7: =IFERROR(__xludf.DUMMYFUNCTION("""COMPUTED_VALUE"""),6100.0) -> 6100 | I7: =IFERROR(__xludf.DUMMYFUNCTION("""COMPUTED_VALUE"""),6950.0) -> 6950 | J7: =IFERROR(__xludf.DUMMYFUNCTION("""COMPUTED_VALUE"""),7700.0) -> 7700 | K7: =IFERROR(__xludf.DUMMYFUNCTION("""COMPUTED_VALUE"""),8400.0) -> 8400 | L7: =IFERROR(__xludf.DUMMYFUNCTION("""COMPUTED_VALUE"""),9100.0) -> 9100 | M7: =IFERROR(__xludf.DUMMYFUNCTION("""COMPUTED_VALUE"""),9800.0) -> 9800 | N7: =IFERROR(__xludf.DUMMYFUNCTION("""COMPUTED_VALUE"""),10500.0) -> 10500 | O7: =IFERROR(__xludf.DUMMYFUNCTION("""COMPUTED_VALUE"""),11500.0) -> 11500
C8: =IFERROR(__xludf.DUMMYFUNCTION("""COMPUTED_VALUE"""),"VT Controlsphere Intermediate S5 80%") -> VT Controlsphere Intermediate S5 80% | D8: =round(brank!$D7*100,0)&"%" -> 0% | G8: =IFERROR(__xludf.DUMMYFUNCTION("sparkline( F8 - choose(match(F8, {0, H8:O8}), 0, H8, I8, J8, K8, L8, M8, N8, O8), { ""charttype"", ""bar""; ""max"", choose(match(F8, {0, H8:O8}), H8, I8-H8, J8-I8, K8-J8, L8-K8, M8-L8, N8-M8, O8-N8, 0); ""nan"", ""ignore""; ""color1"""&", iferror(choose(match(F8, {0, H8:O8}), ""#C5C3F2"", ""#B2CBEA"", ""#BAF6FC"", ""#6B94DF"", ""#5558AA"", ""#6e3f98"", ""#C080E4"", ""#F5BDE8"", ""#F5BDE8"" )) } )"),"") | H8: =IFERROR(__xludf.DUMMYFUNCTION("""COMPUTED_VALUE"""),1850.0) -> 1850 | I8: =IFERROR(__xludf.DUMMYFUNCTION("""COMPUTED_VALUE"""),2300.0) -> 2300 | J8: =IFERROR(__xludf.DUMMYFUNCTION("""COMPUTED_VALUE"""),2700.0) -> 2700 | K8: =IFERROR(__xludf.DUMMYFUNCTION("""COMPUTED_VALUE"""),3000.0) -> 3000 | L8: =IFERROR(__xludf.DUMMYFUNCTION("""COMPUTED_VALUE"""),3300.0) -> 3300 | M8: =IFERROR(__xludf.DUMMYFUNCTION("""COMPUTED_VALUE"""),3600.0) -> 3600 | N8: =IFERROR(__xludf.DUMMYFUNCTION("""COMPUTED_VALUE"""),3850.0) -> 3850 | O8: =IFERROR(__xludf.DUMMYFUNCTION("""COMPUTED_VALUE"""),4100.0) -> 4100
B9: Fingertip | C9: =IFERROR(__xludf.DUMMYFUNCTION("""COMPUTED_VALUE"""),"Air Angelic 4 Voltaic Easy 80% (Good Version)") -> Air Angelic 4 Voltaic Easy 80% (Good Version) | D9: =round(brank!$D8*100,0)&"%" -> 0% | G9: =IFERROR(__xludf.DUMMYFUNCTION("sparkline( F9 - choose(match(F9, {0, H9:O9}), 0, H9, I9, J9, K9, L9, M9, N9, O9), { ""charttype"", ""bar""; ""max"", choose(match(F9, {0, H9:O9}), H9, I9-H9, J9-I9, K9-J9, L9-K9, M9-L9, N9-M9, O9-N9, 0); ""nan"", ""ignore""; ""color1"""&", iferror(choose(match(F9, {0, H9:O9}), ""#C5C3F2"", ""#B2CBEA"", ""#BAF6FC"", ""#6B94DF"", ""#5558AA"", ""#6e3f98"", ""#C080E4"", ""#F5BDE8"", ""#F5BDE8"" )) } )"),"") | H9: =IFERROR(__xludf.DUMMYFUNCTION("""COMPUTED_VALUE"""),1050.0) -> 1050 | I9: =IFERROR(__xludf.DUMMYFUNCTION("""COMPUTED_VALUE"""),1600.0) -> 1600 | J9: =IFERROR(__xludf.DUMMYFUNCTION("""COMPUTED_VALUE"""),2000.0) -> 2000 | K9: =IFERROR(__xludf.DUMMYFUNCTION("""COMPUTED_VALUE"""),2400.0) -> 2400 | L9: =IFERROR(__xludf.DUMMYFUNCTION("""COMPUTED_VALUE"""),2700.0) -> 2700 | M9: =IFERROR(__xludf.DUMMYFUNCTION("""COMPUTED_VALUE"""),3000.0) -> 3000 | N9: =IFERROR(__xludf.DUMMYFUNCTION("""COMPUTED_VALUE"""),3300.0) -> 3300 | O9: =IFERROR(__xludf.DUMMYFUNCTION("""COMPUTED_VALUE"""),3600.0) -> 3600
C10: =IFERROR(__xludf.DUMMYFUNCTION("""COMPUTED_VALUE"""),"Cloverrawcontrol Easy 80% Speed") -> Cloverrawcontrol Easy 80% Speed | D10: =round(brank!$D9*100,0)&"%" -> 0% | G10: =IFERROR(__xludf.DUMMYFUNCTION("sparkline( F10 - choose(match(F10, {0, H10:O10}), 0, H10, I10, J10, K10, L10, M10, N10, O10), { ""charttype"", ""bar""; ""max"", choose(match(F10, {0, H10:O10}), H10, I10-H10, J10-I10, K10-J10, L10-K10, M10-L10, N10-M10, O10-N10, 0); ""nan"&""", ""ignore""; ""color1"", iferror(choose(match(F10, {0, H10:O10}), ""#C5C3F2"", ""#B2CBEA"", ""#BAF6FC"", ""#6B94DF"", ""#5558AA"", ""#6e3f98"", ""#C080E4"", ""#F5BDE8"", ""#F5BDE8"" )) } )"),"") | H10: =IFERROR(__xludf.DUMMYFUNCTION("""COMPUTED_VALUE"""),3900.0) -> 3900 | I10: =IFERROR(__xludf.DUMMYFUNCTION("""COMPUTED_VALUE"""),4550.0) -> 4550 | J10: =IFERROR(__xludf.DUMMYFUNCTION("""COMPUTED_VALUE"""),5200.0) -> 5200 | K10: =IFERROR(__xludf.DUMMYFUNCTION("""COMPUTED_VALUE"""),5700.0) -> 5700 | L10: =IFERROR(__xludf.DUMMYFUNCTION("""COMPUTED_VALUE"""),6200.0) -> 6200 | M10: =IFERROR(__xludf.DUMMYFUNCTION("""COMPUTED_VALUE"""),6700.0) -> 6700 | N10: =IFERROR(__xludf.DUMMYFUNCTION("""COMPUTED_VALUE"""),7200.0) -> 7200 | O10: =IFERROR(__xludf.DUMMYFUNCTION("""COMPUTED_VALUE"""),7700.0) -> 7700
C11: =IFERROR(__xludf.DUMMYFUNCTION("""COMPUTED_VALUE"""),"Controlsphere Far, Far Larger 90%") -> Controlsphere Far, Far Larger 90% | D11: =round(brank!$D10*100,0)&"%" -> 0% | G11: =IFERROR(__xludf.DUMMYFUNCTION("sparkline( F11 - choose(match(F11, {0, H11:O11}), 0, H11, I11, J11, K11, L11, M11, N11, O11), { ""charttype"", ""bar""; ""max"", choose(match(F11, {0, H11:O11}), H11, I11-H11, J11-I11, K11-J11, L11-K11, M11-L11, N11-M11, O11-N11, 0); ""nan"&""", ""ignore""; ""color1"", iferror(choose(match(F11, {0, H11:O11}), ""#C5C3F2"", ""#B2CBEA"", ""#BAF6FC"", ""#6B94DF"", ""#5558AA"", ""#6e3f98"", ""#C080E4"", ""#F5BDE8"", ""#F5BDE8"" )) } )"),"") | H11: =IFERROR(__xludf.DUMMYFUNCTION("""COMPUTED_VALUE"""),7600.0) -> 7600 | I11: =IFERROR(__xludf.DUMMYFUNCTION("""COMPUTED_VALUE"""),8150.0) -> 8150 | J11: =IFERROR(__xludf.DUMMYFUNCTION("""COMPUTED_VALUE"""),8700.0) -> 8700 | K11: =IFERROR(__xludf.DUMMYFUNCTION("""COMPUTED_VALUE"""),9200.0) -> 9200 | L11: =IFERROR(__xludf.DUMMYFUNCTION("""COMPUTED_VALUE"""),9800.0) -> 9800 | M11: =IFERROR(__xludf.DUMMYFUNCTION("""COMPUTED_VALUE"""),10200.0) -> 10200 | N11: =IFERROR(__xludf.DUMMYFUNCTION("""COMPUTED_VALUE"""),10900.0) -> 10900 | O11: =IFERROR(__xludf.DUMMYFUNCTION("""COMPUTED_VALUE"""),11500.0) -> 11500
B12: Blending | C12: =IFERROR(__xludf.DUMMYFUNCTION("""COMPUTED_VALUE"""),"PGTI Voltaic Easy 80%") -> PGTI Voltaic Easy 80% | D12: =round(brank!$D11*100,0)&"%" -> 0% | G12: =IFERROR(__xludf.DUMMYFUNCTION("sparkline( F12 - choose(match(F12, {0, H12:O12}), 0, H12, I12, J12, K12, L12, M12, N12, O12), { ""charttype"", ""bar""; ""max"", choose(match(F12, {0, H12:O12}), H12, I12-H12, J12-I12, K12-J12, L12-K12, M12-L12, N12-M12, O12-N12, 0); ""nan"&""", ""ignore""; ""color1"", iferror(choose(match(F12, {0, H12:O12}), ""#C5C3F2"", ""#B2CBEA"", ""#BAF6FC"", ""#6B94DF"", ""#5558AA"", ""#6e3f98"", ""#C080E4"", ""#F5BDE8"", ""#F5BDE8"" )) } )"),"") | H12: =IFERROR(__xludf.DUMMYFUNCTION("""COMPUTED_VALUE"""),350.0) -> 350 | I12: =IFERROR(__xludf.DUMMYFUNCTION("""COMPUTED_VALUE"""),550.0) -> 550 | J12: =IFERROR(__xludf.DUMMYFUNCTION("""COMPUTED_VALUE"""),850.0) -> 850 | K12: =IFERROR(__xludf.DUMMYFUNCTION("""COMPUTED_VALUE"""),1100.0) -> 1100 | L12: =IFERROR(__xludf.DUMMYFUNCTION("""COMPUTED_VALUE"""),1350.0) -> 1350 | M12: =IFERROR(__xludf.DUMMYFUNCTION("""COMPUTED_VALUE"""),1600.0) -> 1600 | N12: =IFERROR(__xludf.DUMMYFUNCTION("""COMPUTED_VALUE"""),1900.0) -> 1900 | O12: =IFERROR(__xludf.DUMMYFUNCTION("""COMPUTED_VALUE"""),2250.0) -> 2250
C13: =IFERROR(__xludf.DUMMYFUNCTION("""COMPUTED_VALUE"""),"Air CELESTIAL No UFO Easy Slowed") -> Air CELESTIAL No UFO Easy Slowed | D13: =round(brank!$D12*100,0)&"%" -> 0% | G13: =IFERROR(__xludf.DUMMYFUNCTION("sparkline( F13 - choose(match(F13, {0, H13:O13}), 0, H13, I13, J13, K13, L13, M13, N13, O13), { ""charttype"", ""bar""; ""max"", choose(match(F13, {0, H13:O13}), H13, I13-H13, J13-I13, K13-J13, L13-K13, M13-L13, N13-M13, O13-N13, 0); ""nan"&""", ""ignore""; ""color1"", iferror(choose(match(F13, {0, H13:O13}), ""#C5C3F2"", ""#B2CBEA"", ""#BAF6FC"", ""#6B94DF"", ""#5558AA"", ""#6e3f98"", ""#C080E4"", ""#F5BDE8"", ""#F5BDE8"" )) } )"),"") | H13: =IFERROR(__xludf.DUMMYFUNCTION("""COMPUTED_VALUE"""),820.0) -> 820 | I13: =IFERROR(__xludf.DUMMYFUNCTION("""COMPUTED_VALUE"""),835.0) -> 835 | J13: =IFERROR(__xludf.DUMMYFUNCTION("""COMPUTED_VALUE"""),850.0) -> 850 | K13: =IFERROR(__xludf.DUMMYFUNCTION("""COMPUTED_VALUE"""),861.0) -> 861 | L13: =IFERROR(__xludf.DUMMYFUNCTION("""COMPUTED_VALUE"""),870.0) -> 870 | M13: =IFERROR(__xludf.DUMMYFUNCTION("""COMPUTED_VALUE"""),878.0) -> 878 | N13: =IFERROR(__xludf.DUMMYFUNCTION("""COMPUTED_VALUE"""),884.0) -> 884 | O13: =IFERROR(__xludf.DUMMYFUNCTION("""COMPUTED_VALUE"""),890.0) -> 890
C14: =IFERROR(__xludf.DUMMYFUNCTION("""COMPUTED_VALUE"""),"Whisphere Small & Slow 55%") -> Whisphere Small & Slow 55% | D14: =round(brank!$D13*100,0)&"%" -> 0% | G14: =IFERROR(__xludf.DUMMYFUNCTION("sparkline( F14 - choose(match(F14, {0, H14:O14}), 0, H14, I14, J14, K14, L14, M14, N14, O14), { ""charttype"", ""bar""; ""max"", choose(match(F14, {0, H14:O14}), H14, I14-H14, J14-I14, K14-J14, L14-K14, M14-L14, N14-M14, O14-N14, 0); ""nan"&""", ""ignore""; ""color1"", iferror(choose(match(F14, {0, H14:O14}), ""#C5C3F2"", ""#B2CBEA"", ""#BAF6FC"", ""#6B94DF"", ""#5558AA"", ""#6e3f98"", ""#C080E4"", ""#F5BDE8"", ""#F5BDE8"" )) } )"),"") | H14: =IFERROR(__xludf.DUMMYFUNCTION("""COMPUTED_VALUE"""),6000.0) -> 6000 | I14: =IFERROR(__xludf.DUMMYFUNCTION("""COMPUTED_VALUE"""),7500.0) -> 7500 | J14: =IFERROR(__xludf.DUMMYFUNCTION("""COMPUTED_VALUE"""),9000.0) -> 9000 | K14: =IFERROR(__xludf.DUMMYFUNCTION("""COMPUTED_VALUE"""),10000.0) -> 10000 | L14: =IFERROR(__xludf.DUMMYFUNCTION("""COMPUTED_VALUE"""),10750.0) -> 10750 | M14: =IFERROR(__xludf.DUMMYFUNCTION("""COMPUTED_VALUE"""),11500.0) -> 11500 | N14: =IFERROR(__xludf.DUMMYFUNCTION("""COMPUTED_VALUE"""),12250.0) -> 12250 | O14: =IFERROR(__xludf.DUMMYFUNCTION("""COMPUTED_VALUE"""),13500.0) -> 13500
A15: Reactive Tracking | B15: Control | C15: =IFERROR(__xludf.DUMMYFUNCTION("""COMPUTED_VALUE"""),"Air Voltaic Invincible 7 Easy 80%") -> Air Voltaic Invincible 7 Easy 80% | D15: =round(brank!$D14*100,0)&"%" -> 0% | G15: =IFERROR(__xludf.DUMMYFUNCTION("sparkline( F15 - choose(match(F15, {0, H15:O15}), 0, H15, I15, J15, K15, L15, M15, N15, O15), { ""charttype"", ""bar""; ""max"", choose(match(F15, {0, H15:O15}), H15, I15-H15, J15-I15, K15-J15, L15-K15, M15-L15, N15-M15, O15-N15, 0); ""nan"&""", ""ignore""; ""color1"", iferror(choose(match(F15, {0, H15:O15}), ""#C5C3F2"", ""#B2CBEA"", ""#BAF6FC"", ""#6B94DF"", ""#5558AA"", ""#6e3f98"", ""#C080E4"", ""#F5BDE8"", ""#F5BDE8"" )) } )"),"") | H15: =IFERROR(__xludf.DUMMYFUNCTION("""COMPUTED_VALUE"""),750.0) -> 750 | I15: =IFERROR(__xludf.DUMMYFUNCTION("""COMPUTED_VALUE"""),1200.0) -> 1200 | J15: =IFERROR(__xludf.DUMMYFUNCTION("""COMPUTED_VALUE"""),1600.0) -> 1600 | K15: =IFERROR(__xludf.DUMMYFUNCTION("""COMPUTED_VALUE"""),1900.0) -> 1900 | L15: =IFERROR(__xludf.DUMMYFUNCTION("""COMPUTED_VALUE"""),2200.0) -> 2200 | M15: =IFERROR(__xludf.DUMMYFUNCTION("""COMPUTED_VALUE"""),2500.0) -> 2500 | N15: =IFERROR(__xludf.DUMMYFUNCTION("""COMPUTED_VALUE"""),2800.0) -> 2800 | O15: =IFERROR(__xludf.DUMMYFUNCTION("""COMPUTED_VALUE"""),3200.0) -> 3200
C16: =IFERROR(__xludf.DUMMYFUNCTION("""COMPUTED_VALUE"""),"Controlsphere OW Long Strafes 90%") -> Controlsphere OW Long Strafes 90% | D16: =round(brank!$D15*100,0)&"%" -> 0% | G16: =IFERROR(__xludf.DUMMYFUNCTION("sparkline( F16 - choose(match(F16, {0, H16:O16}), 0, H16, I16, J16, K16, L16, M16, N16, O16), { ""charttype"", ""bar""; ""max"", choose(match(F16, {0, H16:O16}), H16, I16-H16, J16-I16, K16-J16, L16-K16, M16-L16, N16-M16, O16-N16, 0); ""nan"&""", ""ignore""; ""color1"", iferror(choose(match(F16, {0, H16:O16}), ""#C5C3F2"", ""#B2CBEA"", ""#BAF6FC"", ""#6B94DF"", ""#5558AA"", ""#6e3f98"", ""#C080E4"", ""#F5BDE8"", ""#F5BDE8"" )) } )"),"") | H16: =IFERROR(__xludf.DUMMYFUNCTION("""COMPUTED_VALUE"""),5400.0) -> 5400 | I16: =IFERROR(__xludf.DUMMYFUNCTION("""COMPUTED_VALUE"""),6100.0) -> 6100 | J16: =IFERROR(__xludf.DUMMYFUNCTION("""COMPUTED_VALUE"""),6700.0) -> 6700 | K16: =IFERROR(__xludf.DUMMYFUNCTION("""COMPUTED_VALUE"""),7200.0) -> 7200 | L16: =IFERROR(__xludf.DUMMYFUNCTION("""COMPUTED_VALUE"""),7600.0) -> 7600 | M16: =IFERROR(__xludf.DUMMYFUNCTION("""COMPUTED_VALUE"""),8000.0) -> 8000 | N16: =IFERROR(__xludf.DUMMYFUNCTION("""COMPUTED_VALUE"""),8300.0) -> 8300 | O16: =IFERROR(__xludf.DUMMYFUNCTION("""COMPUTED_VALUE"""),8700.0) -> 8700
B17: Speed | C17: =IFERROR(__xludf.DUMMYFUNCTION("""COMPUTED_VALUE"""),"Flicker Plaza rAim Easy Less Blinks") -> Flicker Plaza rAim Easy Less Blinks | D17: =round(brank!$D16*100,0)&"%" -> 0% | G17: =IFERROR(__xludf.DUMMYFUNCTION("sparkline( F17 - choose(match(F17, {0, H17:O17}), 0, H17, I17, J17, K17, L17, M17, N17, O17), { ""charttype"", ""bar""; ""max"", choose(match(F17, {0, H17:O17}), H17, I17-H17, J17-I17, K17-J17, L17-K17, M17-L17, N17-M17, O17-N17, 0); ""nan"&""", ""ignore""; ""color1"", iferror(choose(match(F17, {0, H17:O17}), ""#C5C3F2"", ""#B2CBEA"", ""#BAF6FC"", ""#6B94DF"", ""#5558AA"", ""#6e3f98"", ""#C080E4"", ""#F5BDE8"", ""#F5BDE8"" )) } )"),"") | H17: =IFERROR(__xludf.DUMMYFUNCTION("""COMPUTED_VALUE"""),858.0) -> 858 | I17: =IFERROR(__xludf.DUMMYFUNCTION("""COMPUTED_VALUE"""),871.0) -> 871 | J17: =IFERROR(__xludf.DUMMYFUNCTION("""COMPUTED_VALUE"""),883.0) -> 883 | K17: =IFERROR(__xludf.DUMMYFUNCTION("""COMPUTED_VALUE"""),890.0) -> 890 | L17: =IFERROR(__xludf.DUMMYFUNCTION("""COMPUTED_VALUE"""),895.0) -> 895 | M17: =IFERROR(__xludf.DUMMYFUNCTION("""COMPUTED_VALUE"""),900.0) -> 900 | N17: =IFERROR(__xludf.DUMMYFUNCTION("""COMPUTED_VALUE"""),904.0) -> 904 | O17: =IFERROR(__xludf.DUMMYFUNCTION("""COMPUTED_VALUE"""),909.0) -> 909
C18: =IFERROR(__xludf.DUMMYFUNCTION("""COMPUTED_VALUE"""),"Polarized Hell Easy 40% Slower") -> Polarized Hell Easy 40% Slower | D18: =round(brank!$D17*100,0)&"%" -> 0% | G18: =IFERROR(__xludf.DUMMYFUNCTION("sparkline( F18 - choose(match(F18, {0, H18:O18}), 0, H18, I18, J18, K18, L18, M18, N18, O18), { ""charttype"", ""bar""; ""max"", choose(match(F18, {0, H18:O18}), H18, I18-H18, J18-I18, K18-J18, L18-K18, M18-L18, N18-M18, O18-N18, 0); ""nan"&""", ""ignore""; ""color1"", iferror(choose(match(F18, {0, H18:O18}), ""#C5C3F2"", ""#B2CBEA"", ""#BAF6FC"", ""#6B94DF"", ""#5558AA"", ""#6e3f98"", ""#C080E4"", ""#F5BDE8"", ""#F5BDE8"" )) } )"),"") | H18: =IFERROR(__xludf.DUMMYFUNCTION("""COMPUTED_VALUE"""),750.0) -> 750 | I18: =IFERROR(__xludf.DUMMYFUNCTION("""COMPUTED_VALUE"""),1100.0) -> 1100 | J18: =IFERROR(__xludf.DUMMYFUNCTION("""COMPUTED_VALUE"""),1400.0) -> 1400 | K18: =IFERROR(__xludf.DUMMYFUNCTION("""COMPUTED_VALUE"""),1600.0) -> 1600 | L18: =IFERROR(__xludf.DUMMYFUNCTION("""COMPUTED_VALUE"""),1800.0) -> 1800 | M18: =IFERROR(__xludf.DUMMYFUNCTION("""COMPUTED_VALUE"""),2000.0) -> 2000 | N18: =IFERROR(__xludf.DUMMYFUNCTION("""COMPUTED_VALUE"""),2150.0) -> 2150 | O18: =IFERROR(__xludf.DUMMYFUNCTION("""COMPUTED_VALUE"""),2500.0) -> 2500
B19: Reading | C19: =IFERROR(__xludf.DUMMYFUNCTION("""COMPUTED_VALUE"""),"Air Pure Intermediate Slower No UFO") -> Air Pure Intermediate Slower No UFO | D19: =round(brank!$D18*100,0)&"%" -> 0% | G19: =IFERROR(__xludf.DUMMYFUNCTION("sparkline( F19 - choose(match(F19, {0, H19:O19}), 0, H19, I19, J19, K19, L19, M19, N19, O19), { ""charttype"", ""bar""; ""max"", choose(match(F19, {0, H19:O19}), H19, I19-H19, J19-I19, K19-J19, L19-K19, M19-L19, N19-M19, O19-N19, 0); ""nan"&""", ""ignore""; ""color1"", iferror(choose(match(F19, {0, H19:O19}), ""#C5C3F2"", ""#B2CBEA"", ""#BAF6FC"", ""#6B94DF"", ""#5558AA"", ""#6e3f98"", ""#C080E4"", ""#F5BDE8"", ""#F5BDE8"" )) } )"),"") | H19: =IFERROR(__xludf.DUMMYFUNCTION("""COMPUTED_VALUE"""),860.0) -> 860 | I19: =IFERROR(__xludf.DUMMYFUNCTION("""COMPUTED_VALUE"""),874.0) -> 874 | J19: =IFERROR(__xludf.DUMMYFUNCTION("""COMPUTED_VALUE"""),886.0) -> 886 | K19: =IFERROR(__xludf.DUMMYFUNCTION("""COMPUTED_VALUE"""),893.0) -> 893 | L19: =IFERROR(__xludf.DUMMYFUNCTION("""COMPUTED_VALUE"""),901.0) -> 901 | M19: =IFERROR(__xludf.DUMMYFUNCTION("""COMPUTED_VALUE"""),907.0) -> 907 | N19: =IFERROR(__xludf.DUMMYFUNCTION("""COMPUTED_VALUE"""),911.0) -> 911 | O19: =IFERROR(__xludf.DUMMYFUNCTION("""COMPUTED_VALUE"""),916.0) -> 916
C20: =IFERROR(__xludf.DUMMYFUNCTION("""COMPUTED_VALUE"""),"Air Voltaic Easy Invincible 4 80%") -> Air Voltaic Easy Invincible 4 80% | D20: =round(brank!$D19*100,0)&"%" -> 0% | G20: =IFERROR(__xludf.DUMMYFUNCTION("sparkline( F20 - choose(match(F20, {0, H20:O20}), 0, H20, I20, J20, K20, L20, M20, N20, O20), { ""charttype"", ""bar""; ""max"", choose(match(F20, {0, H20:O20}), H20, I20-H20, J20-I20, K20-J20, L20-K20, M20-L20, N20-M20, O20-N20, 0); ""nan"&""", ""ignore""; ""color1"", iferror(choose(match(F20, {0, H20:O20}), ""#C5C3F2"", ""#B2CBEA"", ""#BAF6FC"", ""#6B94DF"", ""#5558AA"", ""#6e3f98"", ""#C080E4"", ""#F5BDE8"", ""#F5BDE8"" )) } )"),"") | H20: =IFERROR(__xludf.DUMMYFUNCTION("""COMPUTED_VALUE"""),1100.0) -> 1100 | I20: =IFERROR(__xludf.DUMMYFUNCTION("""COMPUTED_VALUE"""),1600.0) -> 1600 | J20: =IFERROR(__xludf.DUMMYFUNCTION("""COMPUTED_VALUE"""),2100.0) -> 2100 | K20: =IFERROR(__xludf.DUMMYFUNCTION("""COMPUTED_VALUE"""),2450.0) -> 2450 | L20: =IFERROR(__xludf.DUMMYFUNCTION("""COMPUTED_VALUE"""),2800.0) -> 2800 | M20: =IFERROR(__xludf.DUMMYFUNCTION("""COMPUTED_VALUE"""),3150.0) -> 3150 | N20: =IFERROR(__xludf.DUMMYFUNCTION("""COMPUTED_VALUE"""),3400.0) -> 3400 | O20: =IFERROR(__xludf.DUMMYFUNCTION("""COMPUTED_VALUE"""),3800.0) -> 3800
A21: Flick Tech | B21: Speed | C21: =IFERROR(__xludf.DUMMYFUNCTION("""COMPUTED_VALUE"""),"Pokeball Frenzy Auto TE Wide") -> Pokeball Frenzy Auto TE Wide | D21: =round(brank!$D20*100,0)&"%" -> 0% | G21: =IFERROR(__xludf.DUMMYFUNCTION("sparkline( F21 - choose(match(F21, {0, H21:O21}), 0, H21, I21, J21, K21, L21, M21, N21, O21), { ""charttype"", ""bar""; ""max"", choose(match(F21, {0, H21:O21}), H21, I21-H21, J21-I21, K21-J21, L21-K21, M21-L21, N21-M21, O21-N21, 0); ""nan"&""", ""ignore""; ""color1"", iferror(choose(match(F21, {0, H21:O21}), ""#C5C3F2"", ""#B2CBEA"", ""#BAF6FC"", ""#6B94DF"", ""#5558AA"", ""#6e3f98"", ""#C080E4"", ""#F5BDE8"", ""#F5BDE8"" )) } )"),"") | H21: =IFERROR(__xludf.DUMMYFUNCTION("""COMPUTED_VALUE"""),650.0) -> 650 | I21: =IFERROR(__xludf.DUMMYFUNCTION("""COMPUTED_VALUE"""),950.0) -> 950 | J21: =IFERROR(__xludf.DUMMYFUNCTION("""COMPUTED_VALUE"""),1250.0) -> 1250 | K21: =IFERROR(__xludf.DUMMYFUNCTION("""COMPUTED_VALUE"""),1500.0) -> 1500 | L21: =IFERROR(__xludf.DUMMYFUNCTION("""COMPUTED_VALUE"""),1750.0) -> 1750 | M21: =IFERROR(__xludf.DUMMYFUNCTION("""COMPUTED_VALUE"""),2000.0) -> 2000 | N21: =IFERROR(__xludf.DUMMYFUNCTION("""COMPUTED_VALUE"""),2300.0) -> 2300 | O21: =IFERROR(__xludf.DUMMYFUNCTION("""COMPUTED_VALUE"""),2700.0) -> 2700
C22: =IFERROR(__xludf.DUMMYFUNCTION("""COMPUTED_VALUE"""),"1w3ts Reload Larger") -> 1w3ts Reload Larger | D22: =round(brank!$D21*100,0)&"%" -> 0% | G22: =IFERROR(__xludf.DUMMYFUNCTION("sparkline( F22 - choose(match(F22, {0, H22:O22}), 0, H22, I22, J22, K22, L22, M22, N22, O22), { ""charttype"", ""bar""; ""max"", choose(match(F22, {0, H22:O22}), H22, I22-H22, J22-I22, K22-J22, L22-K22, M22-L22, N22-M22, O22-N22, 0); ""nan"&""", ""ignore""; ""color1"", iferror(choose(match(F22, {0, H22:O22}), ""#C5C3F2"", ""#B2CBEA"", ""#BAF6FC"", ""#6B94DF"", ""#5558AA"", ""#6e3f98"", ""#C080E4"", ""#F5BDE8"", ""#F5BDE8"" )) } )"),"") | H22: =IFERROR(__xludf.DUMMYFUNCTION("""COMPUTED_VALUE"""),36.0) -> 36 | I22: =IFERROR(__xludf.DUMMYFUNCTION("""COMPUTED_VALUE"""),43.0) -> 43 | J22: =IFERROR(__xludf.DUMMYFUNCTION("""COMPUTED_VALUE"""),50.0) -> 50 | K22: =IFERROR(__xludf.DUMMYFUNCTION("""COMPUTED_VALUE"""),58.0) -> 58 | L22: =IFERROR(__xludf.DUMMYFUNCTION("""COMPUTED_VALUE"""),70.0) -> 70 | M22: =IFERROR(__xludf.DUMMYFUNCTION("""COMPUTED_VALUE"""),82.0) -> 82 | N22: =IFERROR(__xludf.DUMMYFUNCTION("""COMPUTED_VALUE"""),92.0) -> 92 | O22: =IFERROR(__xludf.DUMMYFUNCTION("""COMPUTED_VALUE"""),102.0) -> 102
C23: =IFERROR(__xludf.DUMMYFUNCTION("""COMPUTED_VALUE"""),"voxTargetSwitch 2 Large") -> voxTargetSwitch 2 Large | D23: =round(brank!$D22*100,0)&"%" -> 0% | G23: =IFERROR(__xludf.DUMMYFUNCTION("sparkline( F23 - choose(match(F23, {0, H23:O23}), 0, H23, I23, J23, K23, L23, M23, N23, O23), { ""charttype"", ""bar""; ""max"", choose(match(F23, {0, H23:O23}), H23, I23-H23, J23-I23, K23-J23, L23-K23, M23-L23, N23-M23, O23-N23, 0); ""nan"&""", ""ignore""; ""color1"", iferror(choose(match(F23, {0, H23:O23}), ""#C5C3F2"", ""#B2CBEA"", ""#BAF6FC"", ""#6B94DF"", ""#5558AA"", ""#6e3f98"", ""#C080E4"", ""#F5BDE8"", ""#F5BDE8"" )) } )"),"") | H23: =IFERROR(__xludf.DUMMYFUNCTION("""COMPUTED_VALUE"""),67.0) -> 67 | I23: =IFERROR(__xludf.DUMMYFUNCTION("""COMPUTED_VALUE"""),78.0) -> 78 | J23: =IFERROR(__xludf.DUMMYFUNCTION("""COMPUTED_VALUE"""),87.0) -> 87 | K23: =IFERROR(__xludf.DUMMYFUNCTION("""COMPUTED_VALUE"""),95.0) -> 95 | L23: =IFERROR(__xludf.DUMMYFUNCTION("""COMPUTED_VALUE"""),103.0) -> 103 | M23: =IFERROR(__xludf.DUMMYFUNCTION("""COMPUTED_VALUE"""),110.0) -> 110 | N23: =IFERROR(__xludf.DUMMYFUNCTION("""COMPUTED_VALUE"""),117.0) -> 117 | O23: =IFERROR(__xludf.DUMMYFUNCTION("""COMPUTED_VALUE"""),123.0) -> 123
B24: Stability | C24: =IFERROR(__xludf.DUMMYFUNCTION("""COMPUTED_VALUE"""),"BeanTS Larger") -> BeanTS Larger | D24: =round(brank!$D23*100,0)&"%" -> 0% | G24: =IFERROR(__xludf.DUMMYFUNCTION("sparkline( F24 - choose(match(F24, {0, H24:O24}), 0, H24, I24, J24, K24, L24, M24, N24, O24), { ""charttype"", ""bar""; ""max"", choose(match(F24, {0, H24:O24}), H24, I24-H24, J24-I24, K24-J24, L24-K24, M24-L24, N24-M24, O24-N24, 0); ""nan"&""", ""ignore""; ""color1"", iferror(choose(match(F24, {0, H24:O24}), ""#C5C3F2"", ""#B2CBEA"", ""#BAF6FC"", ""#6B94DF"", ""#5558AA"", ""#6e3f98"", ""#C080E4"", ""#F5BDE8"", ""#F5BDE8"" )) } )"),"") | H24: =IFERROR(__xludf.DUMMYFUNCTION("""COMPUTED_VALUE"""),65.0) -> 65 | I24: =IFERROR(__xludf.DUMMYFUNCTION("""COMPUTED_VALUE"""),78.0) -> 78 | J24: =IFERROR(__xludf.DUMMYFUNCTION("""COMPUTED_VALUE"""),90.0) -> 90 | K24: =IFERROR(__xludf.DUMMYFUNCTION("""COMPUTED_VALUE"""),100.0) -> 100 | L24: =IFERROR(__xludf.DUMMYFUNCTION("""COMPUTED_VALUE"""),110.0) -> 110 | M24: =IFERROR(__xludf.DUMMYFUNCTION("""COMPUTED_VALUE"""),120.0) -> 120 | N24: =IFERROR(__xludf.DUMMYFUNCTION("""COMPUTED_VALUE"""),130.0) -> 130 | O24: =IFERROR(__xludf.DUMMYFUNCTION("""COMPUTED_VALUE"""),142.0) -> 142
C25: =IFERROR(__xludf.DUMMYFUNCTION("""COMPUTED_VALUE"""),"FloatTS Angelic Easy Larger") -> FloatTS Angelic Easy Larger | D25: =round(brank!$D24*100,0)&"%" -> 0% | G25: =IFERROR(__xludf.DUMMYFUNCTION("sparkline( F25 - choose(match(F25, {0, H25:O25}), 0, H25, I25, J25, K25, L25, M25, N25, O25), { ""charttype"", ""bar""; ""max"", choose(match(F25, {0, H25:O25}), H25, I25-H25, J25-I25, K25-J25, L25-K25, M25-L25, N25-M25, O25-N25, 0); ""nan"&""", ""ignore""; ""color1"", iferror(choose(match(F25, {0, H25:O25}), ""#C5C3F2"", ""#B2CBEA"", ""#BAF6FC"", ""#6B94DF"", ""#5558AA"", ""#6e3f98"", ""#C080E4"", ""#F5BDE8"", ""#F5BDE8"" )) } )"),"") | H25: =IFERROR(__xludf.DUMMYFUNCTION("""COMPUTED_VALUE"""),65.0) -> 65 | I25: =IFERROR(__xludf.DUMMYFUNCTION("""COMPUTED_VALUE"""),74.0) -> 74 | J25: =IFERROR(__xludf.DUMMYFUNCTION("""COMPUTED_VALUE"""),81.0) -> 81 | K25: =IFERROR(__xludf.DUMMYFUNCTION("""COMPUTED_VALUE"""),88.0) -> 88 | L25: =IFERROR(__xludf.DUMMYFUNCTION("""COMPUTED_VALUE"""),95.0) -> 95 | M25: =IFERROR(__xludf.DUMMYFUNCTION("""COMPUTED_VALUE"""),101.0) -> 101 | N25: =IFERROR(__xludf.DUMMYFUNCTION("""COMPUTED_VALUE"""),106.0) -> 106 | O25: =IFERROR(__xludf.DUMMYFUNCTION("""COMPUTED_VALUE"""),111.0) -> 111
B26: Micro | C26: =IFERROR(__xludf.DUMMYFUNCTION("""COMPUTED_VALUE"""),"WaldoTS Novice") -> WaldoTS Novice | D26: =round(brank!$D25*100,0)&"%" -> 0% | G26: =IFERROR(__xludf.DUMMYFUNCTION("sparkline( F26 - choose(match(F26, {0, H26:O26}), 0, H26, I26, J26, K26, L26, M26, N26, O26), { ""charttype"", ""bar""; ""max"", choose(match(F26, {0, H26:O26}), H26, I26-H26, J26-I26, K26-J26, L26-K26, M26-L26, N26-M26, O26-N26, 0); ""nan"&""", ""ignore""; ""color1"", iferror(choose(match(F26, {0, H26:O26}), ""#C5C3F2"", ""#B2CBEA"", ""#BAF6FC"", ""#6B94DF"", ""#5558AA"", ""#6e3f98"", ""#C080E4"", ""#F5BDE8"", ""#F5BDE8"" )) } )"),"") | H26: =IFERROR(__xludf.DUMMYFUNCTION("""COMPUTED_VALUE"""),65.0) -> 65 | I26: =IFERROR(__xludf.DUMMYFUNCTION("""COMPUTED_VALUE"""),78.0) -> 78 | J26: =IFERROR(__xludf.DUMMYFUNCTION("""COMPUTED_VALUE"""),90.0) -> 90 | K26: =IFERROR(__xludf.DUMMYFUNCTION("""COMPUTED_VALUE"""),100.0) -> 100 | L26: =IFERROR(__xludf.DUMMYFUNCTION("""COMPUTED_VALUE"""),110.0) -> 110 | M26: =IFERROR(__xludf.DUMMYFUNCTION("""COMPUTED_VALUE"""),120.0) -> 120 | N26: =IFERROR(__xludf.DUMMYFUNCTION("""COMPUTED_VALUE"""),130.0) -> 130 | O26: =IFERROR(__xludf.DUMMYFUNCTION("""COMPUTED_VALUE"""),140.0) -> 140
C27: =IFERROR(__xludf.DUMMYFUNCTION("""COMPUTED_VALUE"""),"devTS Goated NR Static 5Bot") -> devTS Goated NR Static 5Bot | D27: =round(brank!$D26*100,0)&"%" -> 0% | G27: =IFERROR(__xludf.DUMMYFUNCTION("sparkline( F27 - choose(match(F27, {0, H27:O27}), 0, H27, I27, J27, K27, L27, M27, N27, O27), { ""charttype"", ""bar""; ""max"", choose(match(F27, {0, H27:O27}), H27, I27-H27, J27-I27, K27-J27, L27-K27, M27-L27, N27-M27, O27-N27, 0); ""nan"&""", ""ignore""; ""color1"", iferror(choose(match(F27, {0, H27:O27}), ""#C5C3F2"", ""#B2CBEA"", ""#BAF6FC"", ""#6B94DF"", ""#5558AA"", ""#6e3f98"", ""#C080E4"", ""#F5BDE8"", ""#F5BDE8"" )) } )"),"") | H27: =IFERROR(__xludf.DUMMYFUNCTION("""COMPUTED_VALUE"""),350.0) -> 350 | I27: =IFERROR(__xludf.DUMMYFUNCTION("""COMPUTED_VALUE"""),400.0) -> 400 | J27: =IFERROR(__xludf.DUMMYFUNCTION("""COMPUTED_VALUE"""),450.0) -> 450 | K27: =IFERROR(__xludf.DUMMYFUNCTION("""COMPUTED_VALUE"""),500.0) -> 500 | L27: =IFERROR(__xludf.DUMMYFUNCTION("""COMPUTED_VALUE"""),550.0) -> 550 | M27: =IFERROR(__xludf.DUMMYFUNCTION("""COMPUTED_VALUE"""),600.0) -> 600 | N27: =IFERROR(__xludf.DUMMYFUNCTION("""COMPUTED_VALUE"""),640.0) -> 640 | O27: =IFERROR(__xludf.DUMMYFUNCTION("""COMPUTED_VALUE"""),680.0) -> 680
B28: Evasive | C28: =IFERROR(__xludf.DUMMYFUNCTION("""COMPUTED_VALUE"""),"domiSwitch Easy Slower") -> domiSwitch Easy Slower | D28: =round(brank!$D27*100,0)&"%" -> 0% | G28: =IFERROR(__xludf.DUMMYFUNCTION("sparkline( F28 - choose(match(F28, {0, H28:O28}), 0, H28, I28, J28, K28, L28, M28, N28, O28), { ""charttype"", ""bar""; ""max"", choose(match(F28, {0, H28:O28}), H28, I28-H28, J28-I28, K28-J28, L28-K28, M28-L28, N28-M28, O28-N28, 0); ""nan"&""", ""ignore""; ""color1"", iferror(choose(match(F28, {0, H28:O28}), ""#C5C3F2"", ""#B2CBEA"", ""#BAF6FC"", ""#6B94DF"", ""#5558AA"", ""#6e3f98"", ""#C080E4"", ""#F5BDE8"", ""#F5BDE8"" )) } )"),"") | H28: =IFERROR(__xludf.DUMMYFUNCTION("""COMPUTED_VALUE"""),3200.0) -> 3200 | I28: =IFERROR(__xludf.DUMMYFUNCTION("""COMPUTED_VALUE"""),3700.0) -> 3700 | J28: =IFERROR(__xludf.DUMMYFUNCTION("""COMPUTED_VALUE"""),4200.0) -> 4200 | K28: =IFERROR(__xludf.DUMMYFUNCTION("""COMPUTED_VALUE"""),4600.0) -> 4600 | L28: =IFERROR(__xludf.DUMMYFUNCTION("""COMPUTED_VALUE"""),5000.0) -> 5000 | M28: =IFERROR(__xludf.DUMMYFUNCTION("""COMPUTED_VALUE"""),5400.0) -> 5400 | N28: =IFERROR(__xludf.DUMMYFUNCTION("""COMPUTED_VALUE"""),5800.0) -> 5800 | O28: =IFERROR(__xludf.DUMMYFUNCTION("""COMPUTED_VALUE"""),6300.0) -> 6300
C29: =IFERROR(__xludf.DUMMYFUNCTION("""COMPUTED_VALUE"""),"tamTargetSwitch Smooth Easy") -> tamTargetSwitch Smooth Easy | D29: =round(brank!$D28*100,0)&"%" -> 0% | G29: =IFERROR(__xludf.DUMMYFUNCTION("sparkline( F29 - choose(match(F29, {0, H29:O29}), 0, H29, I29, J29, K29, L29, M29, N29, O29), { ""charttype"", ""bar""; ""max"", choose(match(F29, {0, H29:O29}), H29, I29-H29, J29-I29, K29-J29, L29-K29, M29-L29, N29-M29, O29-N29, 0); ""nan"&""", ""ignore""; ""color1"", iferror(choose(match(F29, {0, H29:O29}), ""#C5C3F2"", ""#B2CBEA"", ""#BAF6FC"", ""#6B94DF"", ""#5558AA"", ""#6e3f98"", ""#C080E4"", ""#F5BDE8"", ""#F5BDE8"" )) } )"),"") | H29: =IFERROR(__xludf.DUMMYFUNCTION("""COMPUTED_VALUE"""),7.0) -> 7 | I29: =IFERROR(__xludf.DUMMYFUNCTION("""COMPUTED_VALUE"""),11.0) -> 11 | J29: =IFERROR(__xludf.DUMMYFUNCTION("""COMPUTED_VALUE"""),15.0) -> 15 | K29: =IFERROR(__xludf.DUMMYFUNCTION("""COMPUTED_VALUE"""),18.0) -> 18 | L29: =IFERROR(__xludf.DUMMYFUNCTION("""COMPUTED_VALUE"""),21.0) -> 21 | M29: =IFERROR(__xludf.DUMMYFUNCTION("""COMPUTED_VALUE"""),24.0) -> 24 | N29: =IFERROR(__xludf.DUMMYFUNCTION("""COMPUTED_VALUE"""),26.0) -> 26 | O29: =IFERROR(__xludf.DUMMYFUNCTION("""COMPUTED_VALUE"""),28.0) -> 28
A30: Dynamic Clicking | B30: Reading | C30: =IFERROR(__xludf.DUMMYFUNCTION("""COMPUTED_VALUE"""),"1wall5targets_pasu slow") -> 1wall5targets_pasu slow | D30: =round(brank!$D29*100,0)&"%" -> 0% | G30: =IFERROR(__xludf.DUMMYFUNCTION("sparkline( F30 - choose(match(F30, {0, H30:O30}), 0, H30, I30, J30, K30, L30, M30, N30, O30), { ""charttype"", ""bar""; ""max"", choose(match(F30, {0, H30:O30}), H30, I30-H30, J30-I30, K30-J30, L30-K30, M30-L30, N30-M30, O30-N30, 0); ""nan"&""", ""ignore""; ""color1"", iferror(choose(match(F30, {0, H30:O30}), ""#C5C3F2"", ""#B2CBEA"", ""#BAF6FC"", ""#6B94DF"", ""#5558AA"", ""#6e3f98"", ""#C080E4"", ""#F5BDE8"", ""#F5BDE8"" )) } )"),"") | H30: =IFERROR(__xludf.DUMMYFUNCTION("""COMPUTED_VALUE"""),76.0) -> 76 | I30: =IFERROR(__xludf.DUMMYFUNCTION("""COMPUTED_VALUE"""),88.0) -> 88 | J30: =IFERROR(__xludf.DUMMYFUNCTION("""COMPUTED_VALUE"""),100.0) -> 100 | K30: =IFERROR(__xludf.DUMMYFUNCTION("""COMPUTED_VALUE"""),110.0) -> 110 | L30: =IFERROR(__xludf.DUMMYFUNCTION("""COMPUTED_VALUE"""),120.0) -> 120 | M30: =IFERROR(__xludf.DUMMYFUNCTION("""COMPUTED_VALUE"""),130.0) -> 130 | N30: =IFERROR(__xludf.DUMMYFUNCTION("""COMPUTED_VALUE"""),140.0) -> 140 | O30: =IFERROR(__xludf.DUMMYFUNCTION("""COMPUTED_VALUE"""),150.0) -> 150
C31: =IFERROR(__xludf.DUMMYFUNCTION("""COMPUTED_VALUE"""),"B180 Voltaic Easy 92%") -> B180 Voltaic Easy 92% | D31: =round(brank!$D30*100,0)&"%" -> 0% | G31: =IFERROR(__xludf.DUMMYFUNCTION("sparkline( F31 - choose(match(F31, {0, H31:O31}), 0, H31, I31, J31, K31, L31, M31, N31, O31), { ""charttype"", ""bar""; ""max"", choose(match(F31, {0, H31:O31}), H31, I31-H31, J31-I31, K31-J31, L31-K31, M31-L31, N31-M31, O31-N31, 0); ""nan"&""", ""ignore""; ""color1"", iferror(choose(match(F31, {0, H31:O31}), ""#C5C3F2"", ""#B2CBEA"", ""#BAF6FC"", ""#6B94DF"", ""#5558AA"", ""#6e3f98"", ""#C080E4"", ""#F5BDE8"", ""#F5BDE8"" )) } )"),"") | H31: =IFERROR(__xludf.DUMMYFUNCTION("""COMPUTED_VALUE"""),26.0) -> 26 | I31: =IFERROR(__xludf.DUMMYFUNCTION("""COMPUTED_VALUE"""),38.0) -> 38 | J31: =IFERROR(__xludf.DUMMYFUNCTION("""COMPUTED_VALUE"""),50.0) -> 50 | K31: =IFERROR(__xludf.DUMMYFUNCTION("""COMPUTED_VALUE"""),58.0) -> 58 | L31: =IFERROR(__xludf.DUMMYFUNCTION("""COMPUTED_VALUE"""),65.0) -> 65 | M31: =IFERROR(__xludf.DUMMYFUNCTION("""COMPUTED_VALUE"""),72.0) -> 72 | N31: =IFERROR(__xludf.DUMMYFUNCTION("""COMPUTED_VALUE"""),78.0) -> 78 | O31: =IFERROR(__xludf.DUMMYFUNCTION("""COMPUTED_VALUE"""),87.0) -> 87
C32: =IFERROR(__xludf.DUMMYFUNCTION("""COMPUTED_VALUE"""),"Controlsphere Click Easy") -> Controlsphere Click Easy | D32: =round(brank!$D31*100,0)&"%" -> 0% | G32: =IFERROR(__xludf.DUMMYFUNCTION("sparkline( F32 - choose(match(F32, {0, H32:O32}), 0, H32, I32, J32, K32, L32, M32, N32, O32), { ""charttype"", ""bar""; ""max"", choose(match(F32, {0, H32:O32}), H32, I32-H32, J32-I32, K32-J32, L32-K32, M32-L32, N32-M32, O32-N32, 0); ""nan"&""", ""ignore""; ""color1"", iferror(choose(match(F32, {0, H32:O32}), ""#C5C3F2"", ""#B2CBEA"", ""#BAF6FC"", ""#6B94DF"", ""#5558AA"", ""#6e3f98"", ""#C080E4"", ""#F5BDE8"", ""#F5BDE8"" )) } )"),"") | H32: =IFERROR(__xludf.DUMMYFUNCTION("""COMPUTED_VALUE"""),15.0) -> 15 | I32: =IFERROR(__xludf.DUMMYFUNCTION("""COMPUTED_VALUE"""),21.0) -> 21 | J32: =IFERROR(__xludf.DUMMYFUNCTION("""COMPUTED_VALUE"""),27.0) -> 27 | K32: =IFERROR(__xludf.DUMMYFUNCTION("""COMPUTED_VALUE"""),33.0) -> 33 | L32: =IFERROR(__xludf.DUMMYFUNCTION("""COMPUTED_VALUE"""),39.0) -> 39 | M32: =IFERROR(__xludf.DUMMYFUNCTION("""COMPUTED_VALUE"""),45.0) -> 45 | N32: =IFERROR(__xludf.DUMMYFUNCTION("""COMPUTED_VALUE"""),50.0) -> 50 | O32: =IFERROR(__xludf.DUMMYFUNCTION("""COMPUTED_VALUE"""),55.0) -> 55
B33: Precision | C33: =IFERROR(__xludf.DUMMYFUNCTION("""COMPUTED_VALUE"""),"Popcorn MV Novice") -> Popcorn MV Novice | D33: =round(brank!$D32*100,0)&"%" -> 0% | G33: =IFERROR(__xludf.DUMMYFUNCTION("sparkline( F33 - choose(match(F33, {0, H33:O33}), 0, H33, I33, J33, K33, L33, M33, N33, O33), { ""charttype"", ""bar""; ""max"", choose(match(F33, {0, H33:O33}), H33, I33-H33, J33-I33, K33-J33, L33-K33, M33-L33, N33-M33, O33-N33, 0); ""nan"&""", ""ignore""; ""color1"", iferror(choose(match(F33, {0, H33:O33}), ""#C5C3F2"", ""#B2CBEA"", ""#BAF6FC"", ""#6B94DF"", ""#5558AA"", ""#6e3f98"", ""#C080E4"", ""#F5BDE8"", ""#F5BDE8"" )) } )"),"") | H33: =IFERROR(__xludf.DUMMYFUNCTION("""COMPUTED_VALUE"""),50.0) -> 50 | I33: =IFERROR(__xludf.DUMMYFUNCTION("""COMPUTED_VALUE"""),100.0) -> 100 | J33: =IFERROR(__xludf.DUMMYFUNCTION("""COMPUTED_VALUE"""),150.0) -> 150 | K33: =IFERROR(__xludf.DUMMYFUNCTION("""COMPUTED_VALUE"""),190.0) -> 190 | L33: =IFERROR(__xludf.DUMMYFUNCTION("""COMPUTED_VALUE"""),230.0) -> 230 | M33: =IFERROR(__xludf.DUMMYFUNCTION("""COMPUTED_VALUE"""),270.0) -> 270 | N33: =IFERROR(__xludf.DUMMYFUNCTION("""COMPUTED_VALUE"""),300.0) -> 300 | O33: =IFERROR(__xludf.DUMMYFUNCTION("""COMPUTED_VALUE"""),330.0) -> 330
C34: =IFERROR(__xludf.DUMMYFUNCTION("""COMPUTED_VALUE"""),"Pasu Angelic 20% Larger 80% Speed") -> Pasu Angelic 20% Larger 80% Speed | D34: =round(brank!$D33*100,0)&"%" -> 0% | G34: =IFERROR(__xludf.DUMMYFUNCTION("sparkline( F34 - choose(match(F34, {0, H34:O34}), 0, H34, I34, J34, K34, L34, M34, N34, O34), { ""charttype"", ""bar""; ""max"", choose(match(F34, {0, H34:O34}), H34, I34-H34, J34-I34, K34-J34, L34-K34, M34-L34, N34-M34, O34-N34, 0); ""nan"&""", ""ignore""; ""color1"", iferror(choose(match(F34, {0, H34:O34}), ""#C5C3F2"", ""#B2CBEA"", ""#BAF6FC"", ""#6B94DF"", ""#5558AA"", ""#6e3f98"", ""#C080E4"", ""#F5BDE8"", ""#F5BDE8"" )) } )"),"") | H34: =IFERROR(__xludf.DUMMYFUNCTION("""COMPUTED_VALUE"""),51.0) -> 51 | I34: =IFERROR(__xludf.DUMMYFUNCTION("""COMPUTED_VALUE"""),58.0) -> 58 | J34: =IFERROR(__xludf.DUMMYFUNCTION("""COMPUTED_VALUE"""),65.0) -> 65 | K34: =IFERROR(__xludf.DUMMYFUNCTION("""COMPUTED_VALUE"""),72.0) -> 72 | L34: =IFERROR(__xludf.DUMMYFUNCTION("""COMPUTED_VALUE"""),78.0) -> 78 | M34: =IFERROR(__xludf.DUMMYFUNCTION("""COMPUTED_VALUE"""),84.0) -> 84 | N34: =IFERROR(__xludf.DUMMYFUNCTION("""COMPUTED_VALUE"""),90.0) -> 90 | O34: =IFERROR(__xludf.DUMMYFUNCTION("""COMPUTED_VALUE"""),97.0) -> 97
C35: =IFERROR(__xludf.DUMMYFUNCTION("""COMPUTED_VALUE"""),"1w2ts Pasu Perfected Easy") -> 1w2ts Pasu Perfected Easy | D35: =round(brank!$D34*100,0)&"%" -> 0% | G35: =IFERROR(__xludf.DUMMYFUNCTION("sparkline( F35 - choose(match(F35, {0, H35:O35}), 0, H35, I35, J35, K35, L35, M35, N35, O35), { ""charttype"", ""bar""; ""max"", choose(match(F35, {0, H35:O35}), H35, I35-H35, J35-I35, K35-J35, L35-K35, M35-L35, N35-M35, O35-N35, 0); ""nan"&""", ""ignore""; ""color1"", iferror(choose(match(F35, {0, H35:O35}), ""#C5C3F2"", ""#B2CBEA"", ""#BAF6FC"", ""#6B94DF"", ""#5558AA"", ""#6e3f98"", ""#C080E4"", ""#F5BDE8"", ""#F5BDE8"" )) } )"),"") | H35: =IFERROR(__xludf.DUMMYFUNCTION("""COMPUTED_VALUE"""),58.0) -> 58 | I35: =IFERROR(__xludf.DUMMYFUNCTION("""COMPUTED_VALUE"""),69.0) -> 69 | J35: =IFERROR(__xludf.DUMMYFUNCTION("""COMPUTED_VALUE"""),80.0) -> 80 | K35: =IFERROR(__xludf.DUMMYFUNCTION("""COMPUTED_VALUE"""),87.0) -> 87 | L35: =IFERROR(__xludf.DUMMYFUNCTION("""COMPUTED_VALUE"""),93.0) -> 93 | M35: =IFERROR(__xludf.DUMMYFUNCTION("""COMPUTED_VALUE"""),99.0) -> 99 | N35: =IFERROR(__xludf.DUMMYFUNCTION("""COMPUTED_VALUE"""),105.0) -> 105 | O35: =IFERROR(__xludf.DUMMYFUNCTION("""COMPUTED_VALUE"""),110.0) -> 110
B36: Linear | C36: =IFERROR(__xludf.DUMMYFUNCTION("""COMPUTED_VALUE"""),"1w3ts Pasu Perfected Micro Goated Larger 80%") -> 1w3ts Pasu Perfected Micro Goated Larger 80% | D36: =round(brank!$D35*100,0)&"%" -> 0% | G36: =IFERROR(__xludf.DUMMYFUNCTION("sparkline( F36 - choose(match(F36, {0, H36:O36}), 0, H36, I36, J36, K36, L36, M36, N36, O36), { ""charttype"", ""bar""; ""max"", choose(match(F36, {0, H36:O36}), H36, I36-H36, J36-I36, K36-J36, L36-K36, M36-L36, N36-M36, O36-N36, 0); ""nan"&""", ""ignore""; ""color1"", iferror(choose(match(F36, {0, H36:O36}), ""#C5C3F2"", ""#B2CBEA"", ""#BAF6FC"", ""#6B94DF"", ""#5558AA"", ""#6e3f98"", ""#C080E4"", ""#F5BDE8"", ""#F5BDE8"" )) } )"),"") | H36: =IFERROR(__xludf.DUMMYFUNCTION("""COMPUTED_VALUE"""),600.0) -> 600 | I36: =IFERROR(__xludf.DUMMYFUNCTION("""COMPUTED_VALUE"""),700.0) -> 700 | J36: =IFERROR(__xludf.DUMMYFUNCTION("""COMPUTED_VALUE"""),800.0) -> 800 | K36: =IFERROR(__xludf.DUMMYFUNCTION("""COMPUTED_VALUE"""),900.0) -> 900 | L36: =IFERROR(__xludf.DUMMYFUNCTION("""COMPUTED_VALUE"""),1000.0) -> 1000 | M36: =IFERROR(__xludf.DUMMYFUNCTION("""COMPUTED_VALUE"""),1100.0) -> 1100 | N36: =IFERROR(__xludf.DUMMYFUNCTION("""COMPUTED_VALUE"""),1200.0) -> 1200 | O36: =IFERROR(__xludf.DUMMYFUNCTION("""COMPUTED_VALUE"""),1300.0) -> 1300
C37: =IFERROR(__xludf.DUMMYFUNCTION("""COMPUTED_VALUE"""),"Floating Heads Timing 400% Larger") -> Floating Heads Timing 400% Larger | D37: =round(brank!$D36*100,0)&"%" -> 0% | G37: =IFERROR(__xludf.DUMMYFUNCTION("sparkline( F37 - choose(match(F37, {0, H37:O37}), 0, H37, I37, J37, K37, L37, M37, N37, O37), { ""charttype"", ""bar""; ""max"", choose(match(F37, {0, H37:O37}), H37, I37-H37, J37-I37, K37-J37, L37-K37, M37-L37, N37-M37, O37-N37, 0); ""nan"&""", ""ignore""; ""color1"", iferror(choose(match(F37, {0, H37:O37}), ""#C5C3F2"", ""#B2CBEA"", ""#BAF6FC"", ""#6B94DF"", ""#5558AA"", ""#6e3f98"", ""#C080E4"", ""#F5BDE8"", ""#F5BDE8"" )) } )"),"") | H37: =IFERROR(__xludf.DUMMYFUNCTION("""COMPUTED_VALUE"""),400.0) -> 400 | I37: =IFERROR(__xludf.DUMMYFUNCTION("""COMPUTED_VALUE"""),700.0) -> 700 | J37: =IFERROR(__xludf.DUMMYFUNCTION("""COMPUTED_VALUE"""),1000.0) -> 1000 | K37: =IFERROR(__xludf.DUMMYFUNCTION("""COMPUTED_VALUE"""),1350.0) -> 1350 | L37: =IFERROR(__xludf.DUMMYFUNCTION("""COMPUTED_VALUE"""),1700.0) -> 1700 | M37: =IFERROR(__xludf.DUMMYFUNCTION("""COMPUTED_VALUE"""),2050.0) -> 2050 | N37: =IFERROR(__xludf.DUMMYFUNCTION("""COMPUTED_VALUE"""),2400.0) -> 2400 | O37: =IFERROR(__xludf.DUMMYFUNCTION("""COMPUTED_VALUE"""),2750.0) -> 2750
C38: =IFERROR(__xludf.DUMMYFUNCTION("""COMPUTED_VALUE"""),"voxTargetSwitch Click ") -> voxTargetSwitch Click | D38: =round(brank!$D37*100,0)&"%" -> 0% | G38: =IFERROR(__xludf.DUMMYFUNCTION("sparkline( F38 - choose(match(F38, {0, H38:O38}), 0, H38, I38, J38, K38, L38, M38, N38, O38), { ""charttype"", ""bar""; ""max"", choose(match(F38, {0, H38:O38}), H38, I38-H38, J38-I38, K38-J38, L38-K38, M38-L38, N38-M38, O38-N38, 0); ""nan"&""", ""ignore""; ""color1"", iferror(choose(match(F38, {0, H38:O38}), ""#C5C3F2"", ""#B2CBEA"", ""#BAF6FC"", ""#6B94DF"", ""#5558AA"", ""#6e3f98"", ""#C080E4"", ""#F5BDE8"", ""#F5BDE8"" )) } )"),"") | H38: =IFERROR(__xludf.DUMMYFUNCTION("""COMPUTED_VALUE"""),49.0) -> 49 | I38: =IFERROR(__xludf.DUMMYFUNCTION("""COMPUTED_VALUE"""),59.0) -> 59 | J38: =IFERROR(__xludf.DUMMYFUNCTION("""COMPUTED_VALUE"""),67.0) -> 67 | K38: =IFERROR(__xludf.DUMMYFUNCTION("""COMPUTED_VALUE"""),74.0) -> 74 | L38: =IFERROR(__xludf.DUMMYFUNCTION("""COMPUTED_VALUE"""),81.0) -> 81 | M38: =IFERROR(__xludf.DUMMYFUNCTION("""COMPUTED_VALUE"""),88.0) -> 88 | N38: =IFERROR(__xludf.DUMMYFUNCTION("""COMPUTED_VALUE"""),94.0) -> 94 | O38: =IFERROR(__xludf.DUMMYFUNCTION("""COMPUTED_VALUE"""),100.0) -> 100

Sheet Medium Scenarios
A1: Viscose Medium Scenarios | E1: =irank!A1 -> Unranked | H1: ="Playlist Code: " -> Playlist Code: | J1: KovaaKsVibratingFlankedLurker
C2: Scenario | D2: =round((sum(irank!D2:irank!D37)*100),0) -> 0 | E2: =" High Score" -> High Score | G2: Progress | H2: Cinnabar | I2: Vermillion | J2: Saffron | K2: Celadon | L2: Cerulean | M2: Lavender | N2: Indigo | O2: Fuchsia | Q2: MissColourz | R2: Viscose
A3: Control Tracking | B3: Arm | C3: =IFERROR(__xludf.DUMMYFUNCTION("importrange(""https://docs.google.com/spreadsheets/d/1k3XRRwn-mAbvb3rXIODFPrsnkgSEfh0xg1EWJICcSPo/edit?usp=sharing"",""Intermediate!C3:C38"")"),"WhisphereRawControl") -> WhisphereRawControl | D3: =round(irank!$D2*100,0)&"%" -> 0% | G3: =IFERROR(__xludf.DUMMYFUNCTION("sparkline( F3 - choose(match(F3, {0, H3:O3}), 0, H3, I3, J3, K3, L3, M3, N3, O3), { ""charttype"", ""bar""; ""max"", choose(match(F3, {0, H3:O3}), H3, I3-H3, J3-I3, K3-J3, L3-K3, M3-L3, N3-M3, O3-N3, 0); ""nan"", ""ignore""; ""color1"""&", iferror(choose(match(F3, {0, H3:O3}), ""#CE3D30"", ""#F85939"", ""#F1C338"", ""#9CFF91"", ""#02A4D3"", ""#C2C2FF"", ""#5C3896"", ""#C74375"", ""#C74375"" )) } )"),"") | H3: =IFERROR(__xludf.DUMMYFUNCTION("importrange(""https://docs.google.com/spreadsheets/d/1k3XRRwn-mAbvb3rXIODFPrsnkgSEfh0xg1EWJICcSPo/edit?gid=0#gid=0"",""Intermediate!D3:N38"")"),5300.0) -> 5300 | I3: =IFERROR(__xludf.DUMMYFUNCTION("""COMPUTED_VALUE"""),6700.0) -> 6700 | J3: =IFERROR(__xludf.DUMMYFUNCTION("""COMPUTED_VALUE"""),7600.0) -> 7600 | K3: =IFERROR(__xludf.DUMMYFUNCTION("""COMPUTED_VALUE"""),8800.0) -> 8800 | L3: =IFERROR(__xludf.DUMMYFUNCTION("""COMPUTED_VALUE"""),10000.0) -> 10000 | M3: =IFERROR(__xludf.DUMMYFUNCTION("""COMPUTED_VALUE"""),10900.0) -> 10900 | N3: =IFERROR(__xludf.DUMMYFUNCTION("""COMPUTED_VALUE"""),11800.0) -> 11800 | O3: =IFERROR(__xludf.DUMMYFUNCTION("""COMPUTED_VALUE"""),13000.0) -> 13000 | Q3: =IFERROR(__xludf.DUMMYFUNCTION("""COMPUTED_VALUE"""),12408.0) -> 12408 | R3: =IFERROR(__xludf.DUMMYFUNCTION("""COMPUTED_VALUE"""),14739.0) -> 14739
C4: =IFERROR(__xludf.DUMMYFUNCTION("""COMPUTED_VALUE"""),"Whisphere ") -> Whisphere | D4: =round(irank!$D3*100,0)&"%" -> 0% | G4: =IFERROR(__xludf.DUMMYFUNCTION("sparkline( F4 - choose(match(F4, {0, H4:O4}), 0, H4, I4, J4, K4, L4, M4, N4, O4), { ""charttype"", ""bar""; ""max"", choose(match(F4, {0, H4:O4}), H4, I4-H4, J4-I4, K4-J4, L4-K4, M4-L4, N4-M4, O4-N4, 0); ""nan"", ""ignore""; ""color1"""&", iferror(choose(match(F4, {0, H4:O4}), ""#CE3D30"", ""#F85939"", ""#F1C338"", ""#9CFF91"", ""#02A4D3"", ""#C2C2FF"", ""#5C3896"", ""#C74375"", ""#C74375"" )) } )"),"") | H4: =IFERROR(__xludf.DUMMYFUNCTION("""COMPUTED_VALUE"""),5750.0) -> 5750 | I4: =IFERROR(__xludf.DUMMYFUNCTION("""COMPUTED_VALUE"""),8250.0) -> 8250 | J4: =IFERROR(__xludf.DUMMYFUNCTION("""COMPUTED_VALUE"""),10750.0) -> 10750 | K4: =IFERROR(__xludf.DUMMYFUNCTION("""COMPUTED_VALUE"""),13250.0) -> 13250 | L4: =IFERROR(__xludf.DUMMYFUNCTION("""COMPUTED_VALUE"""),15250.0) -> 15250 | M4: =IFERROR(__xludf.DUMMYFUNCTION("""COMPUTED_VALUE"""),17250.0) -> 17250 | N4: =IFERROR(__xludf.DUMMYFUNCTION("""COMPUTED_VALUE"""),19250.0) -> 19250 | O4: =IFERROR(__xludf.DUMMYFUNCTION("""COMPUTED_VALUE"""),20500.0) -> 20500 | Q4: =IFERROR(__xludf.DUMMYFUNCTION("""COMPUTED_VALUE"""),18200.0) -> 18200 | R4: =IFERROR(__xludf.DUMMYFUNCTION("""COMPUTED_VALUE"""),23410.0) -> 23410
C5: =IFERROR(__xludf.DUMMYFUNCTION("""COMPUTED_VALUE"""),"Smoothbot Invincible Goated") -> Smoothbot Invincible Goated | D5: =round(irank!$D4*100,0)&"%" -> 0% | G5: =IFERROR(__xludf.DUMMYFUNCTION("sparkline( F5 - choose(match(F5, {0, H5:O5}), 0, H5, I5, J5, K5, L5, M5, N5, O5), { ""charttype"", ""bar""; ""max"", choose(match(F5, {0, H5:O5}), H5, I5-H5, J5-I5, K5-J5, L5-K5, M5-L5, N5-M5, O5-N5, 0); ""nan"", ""ignore""; ""color1"""&", iferror(choose(match(F5, {0, H5:O5}), ""#CE3D30"", ""#F85939"", ""#F1C338"", ""#9CFF91"", ""#02A4D3"", ""#C2C2FF"", ""#5C3896"", ""#C74375"", ""#C74375"" )) } )"),"") | H5: =IFERROR(__xludf.DUMMYFUNCTION("""COMPUTED_VALUE"""),1700.0) -> 1700 | I5: =IFERROR(__xludf.DUMMYFUNCTION("""COMPUTED_VALUE"""),2200.0) -> 2200 | J5: =IFERROR(__xludf.DUMMYFUNCTION("""COMPUTED_VALUE"""),2750.0) -> 2750 | K5: =IFERROR(__xludf.DUMMYFUNCTION("""COMPUTED_VALUE"""),3250.0) -> 3250 | L5: =IFERROR(__xludf.DUMMYFUNCTION("""COMPUTED_VALUE"""),3800.0) -> 3800 | M5: =IFERROR(__xludf.DUMMYFUNCTION("""COMPUTED_VALUE"""),4300.0) -> 4300 | N5: =IFERROR(__xludf.DUMMYFUNCTION("""COMPUTED_VALUE"""),4650.0) -> 4650 | O5: =IFERROR(__xludf.DUMMYFUNCTION("""COMPUTED_VALUE"""),5000.0) -> 5000 | Q5: =IFERROR(__xludf.DUMMYFUNCTION("""COMPUTED_VALUE"""),4320.0) -> 4320 | R5: =IFERROR(__xludf.DUMMYFUNCTION("""COMPUTED_VALUE"""),5538.0) -> 5538
B6: Wrist | C6: =IFERROR(__xludf.DUMMYFUNCTION("""COMPUTED_VALUE"""),"Leaptrack Goated 75% Slightly Larger") -> Leaptrack Goated 75% Slightly Larger | D6: =round(irank!$D5*100,0)&"%" -> 0% | G6: =IFERROR(__xludf.DUMMYFUNCTION("sparkline( F6 - choose(match(F6, {0, H6:O6}), 0, H6, I6, J6, K6, L6, M6, N6, O6), { ""charttype"", ""bar""; ""max"", choose(match(F6, {0, H6:O6}), H6, I6-H6, J6-I6, K6-J6, L6-K6, M6-L6, N6-M6, O6-N6, 0); ""nan"", ""ignore""; ""color1"""&", iferror(choose(match(F6, {0, H6:O6}), ""#CE3D30"", ""#F85939"", ""#F1C338"", ""#9CFF91"", ""#02A4D3"", ""#C2C2FF"", ""#5C3896"", ""#C74375"", ""#C74375"" )) } )"),"") | H6: =IFERROR(__xludf.DUMMYFUNCTION("""COMPUTED_VALUE"""),1400.0) -> 1400 | I6: =IFERROR(__xludf.DUMMYFUNCTION("""COMPUTED_VALUE"""),1750.0) -> 1750 | J6: =IFERROR(__xludf.DUMMYFUNCTION("""COMPUTED_VALUE"""),2000.0) -> 2000 | K6: =IFERROR(__xludf.DUMMYFUNCTION("""COMPUTED_VALUE"""),2250.0) -> 2250 | L6: =IFERROR(__xludf.DUMMYFUNCTION("""COMPUTED_VALUE"""),2500.0) -> 2500 | M6: =IFERROR(__xludf.DUMMYFUNCTION("""COMPUTED_VALUE"""),2750.0) -> 2750 | N6: =IFERROR(__xludf.DUMMYFUNCTION("""COMPUTED_VALUE"""),3000.0) -> 3000 | O6: =IFERROR(__xludf.DUMMYFUNCTION("""COMPUTED_VALUE"""),3275.0) -> 3275 | Q6: =IFERROR(__xludf.DUMMYFUNCTION("""COMPUTED_VALUE"""),2841.0) -> 2841 | R6: =IFERROR(__xludf.DUMMYFUNCTION("""COMPUTED_VALUE"""),3472.0) -> 3472
C7: =IFERROR(__xludf.DUMMYFUNCTION("""COMPUTED_VALUE"""),"Controlsphere rAim Easy") -> Controlsphere rAim Easy | D7: =round(irank!$D6*100,0)&"%" -> 0% | G7: =IFERROR(__xludf.DUMMYFUNCTION("sparkline( F7 - choose(match(F7, {0, H7:O7}), 0, H7, I7, J7, K7, L7, M7, N7, O7), { ""charttype"", ""bar""; ""max"", choose(match(F7, {0, H7:O7}), H7, I7-H7, J7-I7, K7-J7, L7-K7, M7-L7, N7-M7, O7-N7, 0); ""nan"", ""ignore""; ""color1"""&", iferror(choose(match(F7, {0, H7:O7}), ""#CE3D30"", ""#F85939"", ""#F1C338"", ""#9CFF91"", ""#02A4D3"", ""#C2C2FF"", ""#5C3896"", ""#C74375"", ""#C74375"" )) } )"),"") | H7: =IFERROR(__xludf.DUMMYFUNCTION("""COMPUTED_VALUE"""),7400.0) -> 7400 | I7: =IFERROR(__xludf.DUMMYFUNCTION("""COMPUTED_VALUE"""),8500.0) -> 8500 | J7: =IFERROR(__xludf.DUMMYFUNCTION("""COMPUTED_VALUE"""),9600.0) -> 9600 | K7: =IFERROR(__xludf.DUMMYFUNCTION("""COMPUTED_VALUE"""),10700.0) -> 10700 | L7: =IFERROR(__xludf.DUMMYFUNCTION("""COMPUTED_VALUE"""),11900.0) -> 11900 | M7: =IFERROR(__xludf.DUMMYFUNCTION("""COMPUTED_VALUE"""),13100.0) -> 13100 | N7: =IFERROR(__xludf.DUMMYFUNCTION("""COMPUTED_VALUE"""),14300.0) -> 14300 | O7: =IFERROR(__xludf.DUMMYFUNCTION("""COMPUTED_VALUE"""),15100.0) -> 15100 | Q7: =IFERROR(__xludf.DUMMYFUNCTION("""COMPUTED_VALUE"""),14598.0) -> 14598 | R7: =IFERROR(__xludf.DUMMYFUNCTION("""COMPUTED_VALUE"""),15909.0) -> 15909
C8: =IFERROR(__xludf.DUMMYFUNCTION("""COMPUTED_VALUE"""),"VT Controlsphere Novice S5 Hard") -> VT Controlsphere Novice S5 Hard | D8: =round(irank!$D7*100,0)&"%" -> 0% | G8: =IFERROR(__xludf.DUMMYFUNCTION("sparkline( F8 - choose(match(F8, {0, H8:O8}), 0, H8, I8, J8, K8, L8, M8, N8, O8), { ""charttype"", ""bar""; ""max"", choose(match(F8, {0, H8:O8}), H8, I8-H8, J8-I8, K8-J8, L8-K8, M8-L8, N8-M8, O8-N8, 0); ""nan"", ""ignore""; ""color1"""&", iferror(choose(match(F8, {0, H8:O8}), ""#CE3D30"", ""#F85939"", ""#F1C338"", ""#9CFF91"", ""#02A4D3"", ""#C2C2FF"", ""#5C3896"", ""#C74375"", ""#C74375"" )) } )"),"") | H8: =IFERROR(__xludf.DUMMYFUNCTION("""COMPUTED_VALUE"""),2100.0) -> 2100 | I8: =IFERROR(__xludf.DUMMYFUNCTION("""COMPUTED_VALUE"""),2500.0) -> 2500 | J8: =IFERROR(__xludf.DUMMYFUNCTION("""COMPUTED_VALUE"""),2950.0) -> 2950 | K8: =IFERROR(__xludf.DUMMYFUNCTION("""COMPUTED_VALUE"""),3250.0) -> 3250 | L8: =IFERROR(__xludf.DUMMYFUNCTION("""COMPUTED_VALUE"""),3550.0) -> 3550 | M8: =IFERROR(__xludf.DUMMYFUNCTION("""COMPUTED_VALUE"""),3800.0) -> 3800 | N8: =IFERROR(__xludf.DUMMYFUNCTION("""COMPUTED_VALUE"""),4100.0) -> 4100 | O8: =IFERROR(__xludf.DUMMYFUNCTION("""COMPUTED_VALUE"""),4400.0) -> 4400 | Q8: =IFERROR(__xludf.DUMMYFUNCTION("""COMPUTED_VALUE"""),4218.0) -> 4218 | R8: =IFERROR(__xludf.DUMMYFUNCTION("""COMPUTED_VALUE"""),4881.0) -> 4881
B9: Fingertip | C9: =IFERROR(__xludf.DUMMYFUNCTION("""COMPUTED_VALUE"""),"Air Angelic 4 Voltaic Easy") -> Air Angelic 4 Voltaic Easy | D9: =round(irank!$D8*100,0)&"%" -> 0% | G9: =IFERROR(__xludf.DUMMYFUNCTION("sparkline( F9 - choose(match(F9, {0, H9:O9}), 0, H9, I9, J9, K9, L9, M9, N9, O9), { ""charttype"", ""bar""; ""max"", choose(match(F9, {0, H9:O9}), H9, I9-H9, J9-I9, K9-J9, L9-K9, M9-L9, N9-M9, O9-N9, 0); ""nan"", ""ignore""; ""color1"""&", iferror(choose(match(F9, {0, H9:O9}), ""#CE3D30"", ""#F85939"", ""#F1C338"", ""#9CFF91"", ""#02A4D3"", ""#C2C2FF"", ""#5C3896"", ""#C74375"", ""#C74375"" )) } )"),"") | H9: =IFERROR(__xludf.DUMMYFUNCTION("""COMPUTED_VALUE"""),1900.0) -> 1900 | I9: =IFERROR(__xludf.DUMMYFUNCTION("""COMPUTED_VALUE"""),2300.0) -> 2300 | J9: =IFERROR(__xludf.DUMMYFUNCTION("""COMPUTED_VALUE"""),2650.0) -> 2650 | K9: =IFERROR(__xludf.DUMMYFUNCTION("""COMPUTED_VALUE"""),3000.0) -> 3000 | L9: =IFERROR(__xludf.DUMMYFUNCTION("""COMPUTED_VALUE"""),3400.0) -> 3400 | M9: =IFERROR(__xludf.DUMMYFUNCTION("""COMPUTED_VALUE"""),3750.0) -> 3750 | N9: =IFERROR(__xludf.DUMMYFUNCTION("""COMPUTED_VALUE"""),4100.0) -> 4100 | O9: =IFERROR(__xludf.DUMMYFUNCTION("""COMPUTED_VALUE"""),4450.0) -> 4450 | Q9: =IFERROR(__xludf.DUMMYFUNCTION("""COMPUTED_VALUE"""),4295.0) -> 4295 | R9: =IFERROR(__xludf.DUMMYFUNCTION("""COMPUTED_VALUE"""),4995.0) -> 4995
C10: =IFERROR(__xludf.DUMMYFUNCTION("""COMPUTED_VALUE"""),"Cloverrawcontrol Easy") -> Cloverrawcontrol Easy | D10: =round(irank!$D9*100,0)&"%" -> 0% | G10: =IFERROR(__xludf.DUMMYFUNCTION("sparkline( F10 - choose(match(F10, {0, H10:O10}), 0, H10, I10, J10, K10, L10, M10, N10, O10), { ""charttype"", ""bar""; ""max"", choose(match(F10, {0, H10:O10}), H10, I10-H10, J10-I10, K10-J10, L10-K10, M10-L10, N10-M10, O10-N10, 0); ""nan"&""", ""ignore""; ""color1"", iferror(choose(match(F10, {0, H10:O10}), ""#CE3D30"", ""#F85939"", ""#F1C338"", ""#9CFF91"", ""#02A4D3"", ""#C2C2FF"", ""#5C3896"", ""#C74375"", ""#C74375"" )) } )"),"") | H10: =IFERROR(__xludf.DUMMYFUNCTION("""COMPUTED_VALUE"""),5000.0) -> 5000 | I10: =IFERROR(__xludf.DUMMYFUNCTION("""COMPUTED_VALUE"""),6100.0) -> 6100 | J10: =IFERROR(__xludf.DUMMYFUNCTION("""COMPUTED_VALUE"""),7000.0) -> 7000 | K10: =IFERROR(__xludf.DUMMYFUNCTION("""COMPUTED_VALUE"""),8100.0) -> 8100 | L10: =IFERROR(__xludf.DUMMYFUNCTION("""COMPUTED_VALUE"""),9200.0) -> 9200 | M10: =IFERROR(__xludf.DUMMYFUNCTION("""COMPUTED_VALUE"""),10100.0) -> 10100 | N10: =IFERROR(__xludf.DUMMYFUNCTION("""COMPUTED_VALUE"""),10900.0) -> 10900 | O10: =IFERROR(__xludf.DUMMYFUNCTION("""COMPUTED_VALUE"""),11700.0) -> 11700 | Q10: =IFERROR(__xludf.DUMMYFUNCTION("""COMPUTED_VALUE"""),12084.0) -> 12084 | R10: =IFERROR(__xludf.DUMMYFUNCTION("""COMPUTED_VALUE"""),13788.0) -> 13788
